<?xml version="1.0"?>  
<robot name="racebot">  

  <link name="base_link">  
    <visual>  
      <geometry>  
        <box size="0.47 0.225 0.15"/>  
      </geometry>  
    <origin rpy="0 0 0" xyz="0 0 0"/>  
    <material name="orange">  
        <color rgba="255 165 0 1"/>  
    </material>  
    </visual>  

  </link>  

 

<link name="right_front_wheel">  

    <visual>  

      <geometry>  

        <cylinder length=".08" radius="0.07"/>  

      </geometry>  

      <material name="black">  

        <color rgba="0 0 0 1"/>  

      </material>  

    </visual>  

  </link>  

 

  <joint name="right_front_wheel_joint" type="continuous">  

    <axis xyz="0 0 1"/>  

    <parent link="base_link"/>  

    <child link="right_front_wheel"/>  

    <origin rpy="0 1.57075 1.57075" xyz="0.15 0.15 0"/>  

    <limit effort="100" velocity="100"/>  

    <joint_properties damping="0.0" friction="0.0"/>  

  </joint>  

 

  <link name="right_back_wheel">  

    <visual>  

      <geometry>  

        <cylinder length=".08" radius="0.07"/>  

      </geometry>  

      <material name="black">  

        <color rgba="0 0 0 1"/>  

      </material>  

    </visual>  

  </link>  

 

  <joint name="right_back_wheel_joint" type="continuous">  

    <axis xyz="0 0 1"/>  

    <parent link="base_link"/>  

    <child link="right_back_wheel"/>  

    <origin rpy="0 1.57075 1.57075" xyz="0.15 -0.15  0"/>  

    <limit effort="100" velocity="100"/>  

    <joint_properties damping="0.0" friction="0.0"/>  

</joint>  

 

<link name="left_front_wheel">  

    <visual>  

      <geometry>  

        <cylinder length=".08" radius="0.07"/>  

      </geometry>  

      <material name="black">  

        <color rgba="0 0 0 1"/>  

      </material>  

    </visual>  

  </link>  

 

  <joint name="left_front_wheel_joint" type="continuous">  

    <axis xyz="0 0 1"/>  

    <parent link="base_link"/>  

    <child link="left_front_wheel"/>  

    <origin rpy="0 1.57075 1.57075" xyz="-0.15 0.15 0"/>  

    <limit effort="100" velocity="100"/>  

    <joint_properties damping="0.0" friction="0.0"/>  

  </joint>  

 

  <link name="left_back_wheel">  

    <visual>  

      <geometry>  

        <cylinder length=".08" radius="0.07"/>  

      </geometry>  

      <material name="black">  

        <color rgba="0 0 0 1"/>  

      </material>  

    </visual>  

  </link>  

 

  <joint name="left_back_wheel_joint" type="continuous">  

    <axis xyz="0 0 1"/>  

    <parent link="base_link"/>  

    <child link="left_back_wheel"/>  

    <origin rpy="0 1.57075 1.57075" xyz="-0.15 -0.15 0"/>  

    <limit effort="100" velocity="100"/>  

    <joint_properties damping="0.0" friction="0.0"/>  

  </joint>  

 

  <link name="base_camera_link">  
    <visual>  
      <geometry>  
        <box size=".17 .03 .03"/>  
      </geometry>  
      <material name="blank">  
          <color rgba="0 0 0 1"/>  
      </material>  
    </visual>  
  </link>  

 

  <joint name="base_camera_link_joint" type="continuous">  
    <parent link="base_link"/>  
    <child link="base_camera_link"/>  
    <origin rpy="0 0 1.57075" xyz="0.18 0 0.08"/>  
  </joint>  

  <link name="base_imu_link">
    <visual>
      <geometry>
        <box size=".03 .03 .03"/>
      </geometry>
      <material name="red">
          <color rgba="0 0 0 0.1"/>
      </material>
    </visual>
  </link>



  <joint name="base_imu_link_joint" type="continuous">
    <parent link="base_link"/>
    <child link="base_imu_link"/>
    <origin rpy="0 0 0" xyz="0.08 0 0.235"/>
  </joint>




 <link name="laser">
    <visual>
      <geometry>
        <cylinder length=".04" radius="0.03"/>
      </geometry>
      <material name="blank">
          <color rgba="0 0 0  1"/>
      </material>
    </visual>
  </link>



  <joint name="laser_joint" type="continuous">
    <parent link="base_link"/>
    <child link="laser"/>
    <origin rpy="0 0 0" xyz="0 0 0.08"/>
  </joint>




</robot> 
